2020-05-06 13:52:21,685 ERROR: Exception on /reset_password_request [POST] [in /Users/benliu/PycharmProjects/microblog/venv/lib/python3.7/site-packages/flask/app.py:1891]
Traceback (most recent call last):
  File "/Users/benliu/PycharmProjects/microblog/venv/lib/python3.7/site-packages/flask/app.py", line 2446, in wsgi_app
    response = self.full_dispatch_request()
  File "/Users/benliu/PycharmProjects/microblog/venv/lib/python3.7/site-packages/flask/app.py", line 1951, in full_dispatch_request
    rv = self.handle_user_exception(e)
  File "/Users/benliu/PycharmProjects/microblog/venv/lib/python3.7/site-packages/flask/app.py", line 1820, in handle_user_exception
    reraise(exc_type, exc_value, tb)
  File "/Users/benliu/PycharmProjects/microblog/venv/lib/python3.7/site-packages/flask/_compat.py", line 39, in reraise
    raise value
  File "/Users/benliu/PycharmProjects/microblog/venv/lib/python3.7/site-packages/flask/app.py", line 1949, in full_dispatch_request
    rv = self.dispatch_request()
  File "/Users/benliu/PycharmProjects/microblog/venv/lib/python3.7/site-packages/flask/app.py", line 1935, in dispatch_request
    return self.view_functions[rule.endpoint](**req.view_args)
  File "/Users/benliu/PycharmProjects/microblog/app/routes.py", line 91, in reset_password_request
    if form.validate_on_submit():
  File "/Users/benliu/PycharmProjects/microblog/venv/lib/python3.7/site-packages/flask_wtf/form.py", line 100, in validate_on_submit
    return self.is_submitted() and self.validate()
  File "/Users/benliu/PycharmProjects/microblog/venv/lib/python3.7/site-packages/wtforms/form.py", line 310, in validate
    return super(Form, self).validate(extra)
  File "/Users/benliu/PycharmProjects/microblog/venv/lib/python3.7/site-packages/wtforms/form.py", line 152, in validate
    if not field.validate(self, extra):
  File "/Users/benliu/PycharmProjects/microblog/venv/lib/python3.7/site-packages/wtforms/fields/core.py", line 206, in validate
    stop_validation = self._run_validation_chain(form, chain)
  File "/Users/benliu/PycharmProjects/microblog/venv/lib/python3.7/site-packages/wtforms/fields/core.py", line 226, in _run_validation_chain
    validator(form, self)
TypeError: __init__() takes from 1 to 2 positional arguments but 3 were given
2020-05-06 13:53:43,285 INFO: Microblog startup [in /Users/benliu/PycharmProjects/microblog/app/__init__.py:55]
2020-05-06 13:53:52,684 ERROR: Exception on /reset_password_request [POST] [in /Users/benliu/PycharmProjects/microblog/venv/lib/python3.7/site-packages/flask/app.py:1891]
Traceback (most recent call last):
  File "/Users/benliu/PycharmProjects/microblog/venv/lib/python3.7/site-packages/flask/app.py", line 2446, in wsgi_app
    response = self.full_dispatch_request()
  File "/Users/benliu/PycharmProjects/microblog/venv/lib/python3.7/site-packages/flask/app.py", line 1951, in full_dispatch_request
    rv = self.handle_user_exception(e)
  File "/Users/benliu/PycharmProjects/microblog/venv/lib/python3.7/site-packages/flask/app.py", line 1820, in handle_user_exception
    reraise(exc_type, exc_value, tb)
  File "/Users/benliu/PycharmProjects/microblog/venv/lib/python3.7/site-packages/flask/_compat.py", line 39, in reraise
    raise value
  File "/Users/benliu/PycharmProjects/microblog/venv/lib/python3.7/site-packages/flask/app.py", line 1949, in full_dispatch_request
    rv = self.dispatch_request()
  File "/Users/benliu/PycharmProjects/microblog/venv/lib/python3.7/site-packages/flask/app.py", line 1935, in dispatch_request
    return self.view_functions[rule.endpoint](**req.view_args)
  File "/Users/benliu/PycharmProjects/microblog/app/routes.py", line 91, in reset_password_request
    if form.validate_on_submit():
  File "/Users/benliu/PycharmProjects/microblog/venv/lib/python3.7/site-packages/flask_wtf/form.py", line 100, in validate_on_submit
    return self.is_submitted() and self.validate()
  File "/Users/benliu/PycharmProjects/microblog/venv/lib/python3.7/site-packages/wtforms/form.py", line 310, in validate
    return super(Form, self).validate(extra)
  File "/Users/benliu/PycharmProjects/microblog/venv/lib/python3.7/site-packages/wtforms/form.py", line 152, in validate
    if not field.validate(self, extra):
  File "/Users/benliu/PycharmProjects/microblog/venv/lib/python3.7/site-packages/wtforms/fields/core.py", line 206, in validate
    stop_validation = self._run_validation_chain(form, chain)
  File "/Users/benliu/PycharmProjects/microblog/venv/lib/python3.7/site-packages/wtforms/fields/core.py", line 226, in _run_validation_chain
    validator(form, self)
TypeError: __init__() takes from 1 to 2 positional arguments but 3 were given
2020-05-06 13:55:27,264 INFO: Microblog startup [in /Users/benliu/PycharmProjects/microblog/app/__init__.py:55]
2020-05-06 13:55:35,432 ERROR: Exception on /reset_password_request [POST] [in /Users/benliu/PycharmProjects/microblog/venv/lib/python3.7/site-packages/flask/app.py:1891]
Traceback (most recent call last):
  File "/Users/benliu/PycharmProjects/microblog/venv/lib/python3.7/site-packages/flask_mail.py", line 492, in send
    message.send(connection)
  File "/Users/benliu/PycharmProjects/microblog/venv/lib/python3.7/site-packages/flask_mail.py", line 427, in send
    connection.send(self)
  File "/Users/benliu/PycharmProjects/microblog/venv/lib/python3.7/site-packages/flask_mail.py", line 192, in send
    message.rcpt_options)
  File "/Library/Frameworks/Python.framework/Versions/3.7/lib/python3.7/smtplib.py", line 852, in sendmail
    self.ehlo_or_helo_if_needed()
  File "/Library/Frameworks/Python.framework/Versions/3.7/lib/python3.7/smtplib.py", line 600, in ehlo_or_helo_if_needed
    if not (200 <= self.ehlo()[0] <= 299):
  File "/Library/Frameworks/Python.framework/Versions/3.7/lib/python3.7/smtplib.py", line 440, in ehlo
    self.putcmd(self.ehlo_msg, name or self.local_hostname)
  File "/Library/Frameworks/Python.framework/Versions/3.7/lib/python3.7/smtplib.py", line 367, in putcmd
    self.send(str)
  File "/Library/Frameworks/Python.framework/Versions/3.7/lib/python3.7/smtplib.py", line 359, in send
    raise SMTPServerDisconnected('please run connect() first')
smtplib.SMTPServerDisconnected: please run connect() first

During handling of the above exception, another exception occurred:

Traceback (most recent call last):
  File "/Users/benliu/PycharmProjects/microblog/venv/lib/python3.7/site-packages/flask/app.py", line 2446, in wsgi_app
    response = self.full_dispatch_request()
  File "/Users/benliu/PycharmProjects/microblog/venv/lib/python3.7/site-packages/flask/app.py", line 1951, in full_dispatch_request
    rv = self.handle_user_exception(e)
  File "/Users/benliu/PycharmProjects/microblog/venv/lib/python3.7/site-packages/flask/app.py", line 1820, in handle_user_exception
    reraise(exc_type, exc_value, tb)
  File "/Users/benliu/PycharmProjects/microblog/venv/lib/python3.7/site-packages/flask/_compat.py", line 39, in reraise
    raise value
  File "/Users/benliu/PycharmProjects/microblog/venv/lib/python3.7/site-packages/flask/app.py", line 1949, in full_dispatch_request
    rv = self.dispatch_request()
  File "/Users/benliu/PycharmProjects/microblog/venv/lib/python3.7/site-packages/flask/app.py", line 1935, in dispatch_request
    return self.view_functions[rule.endpoint](**req.view_args)
  File "/Users/benliu/PycharmProjects/microblog/app/routes.py", line 94, in reset_password_request
    send_password_reset_email(user)
  File "/Users/benliu/PycharmProjects/microblog/app/email.py", line 19, in send_password_reset_email
    user=user, token=token))
  File "/Users/benliu/PycharmProjects/microblog/app/email.py", line 9, in send_email
    mail.send(msg)
  File "/Users/benliu/PycharmProjects/microblog/venv/lib/python3.7/site-packages/flask_mail.py", line 492, in send
    message.send(connection)
  File "/Users/benliu/PycharmProjects/microblog/venv/lib/python3.7/site-packages/flask_mail.py", line 152, in __exit__
    self.host.quit()
  File "/Library/Frameworks/Python.framework/Versions/3.7/lib/python3.7/smtplib.py", line 984, in quit
    res = self.docmd("quit")
  File "/Library/Frameworks/Python.framework/Versions/3.7/lib/python3.7/smtplib.py", line 420, in docmd
    self.putcmd(cmd, args)
  File "/Library/Frameworks/Python.framework/Versions/3.7/lib/python3.7/smtplib.py", line 367, in putcmd
    self.send(str)
  File "/Library/Frameworks/Python.framework/Versions/3.7/lib/python3.7/smtplib.py", line 359, in send
    raise SMTPServerDisconnected('please run connect() first')
smtplib.SMTPServerDisconnected: please run connect() first
2020-05-06 13:55:47,018 INFO: Microblog startup [in /Users/benliu/PycharmProjects/microblog/app/__init__.py:55]
